Traceback (most recent call last):
  File "/usr/share/miniconda/envs/gtbook/lib/python3.9/site-packages/jupyter_cache/executors/utils.py", line 58, in single_nb_execution
    executenb(
  File "/usr/share/miniconda/envs/gtbook/lib/python3.9/site-packages/nbclient/client.py", line 1305, in execute
    return NotebookClient(nb=nb, resources=resources, km=km, **kwargs).execute()
  File "/usr/share/miniconda/envs/gtbook/lib/python3.9/site-packages/jupyter_core/utils/__init__.py", line 165, in wrapped
    return loop.run_until_complete(inner)
  File "/usr/share/miniconda/envs/gtbook/lib/python3.9/asyncio/base_events.py", line 647, in run_until_complete
    return future.result()
  File "/usr/share/miniconda/envs/gtbook/lib/python3.9/site-packages/nbclient/client.py", line 705, in async_execute
    await self.async_execute_cell(
  File "/usr/share/miniconda/envs/gtbook/lib/python3.9/site-packages/nbclient/client.py", line 1058, in async_execute_cell
    await self._check_raise_for_error(cell, cell_index, exec_reply)
  File "/usr/share/miniconda/envs/gtbook/lib/python3.9/site-packages/nbclient/client.py", line 914, in _check_raise_for_error
    raise CellExecutionError.from_cell_and_msg(cell, exec_reply_content)
nbclient.exceptions.CellExecutionError: An error occurred while executing the following cell:
------------------
px.imshow(V_k, color_continuous_scale='Turbo',origin="upper", aspect='equal')

------------------


[0;31m---------------------------------------------------------------------------[0m
[0;31mNameError[0m                                 Traceback (most recent call last)
Cell [0;32mIn[5], line 1[0m
[0;32m----> 1[0m px[38;5;241m.[39mimshow([43mV_k[49m, color_continuous_scale[38;5;241m=[39m[38;5;124m'[39m[38;5;124mTurbo[39m[38;5;124m'[39m,origin[38;5;241m=[39m[38;5;124m"[39m[38;5;124mupper[39m[38;5;124m"[39m, aspect[38;5;241m=[39m[38;5;124m'[39m[38;5;124mequal[39m[38;5;124m'[39m)

[0;31mNameError[0m: name 'V_k' is not defined

